# Recoverable Errors

```rs
use std::fs::File;
use std::io::ErrorKind;

fn main() {
    let greeting_file_result = File::open("hello.txt");

    let greeting_file = match greeting_file_result {
        Ok(file) => file,
        Err(error) => match error.kind() {
            ErrorKind::NotFound => match File::create("hello.txt") {
                Ok(fc) => fc,
                Err(e) => panic!("Problem creating the file: {:?}", e),
            },
            other_error => {
                panic!("Problem opening the file: {:?}", other_error);
            }
        },
    };
}
```

Using closures:

```rs
let greeting_file = File::open("hello.txt").unwrap_or_else(|error| {
    if error.kind() == ErrorKind::NotFound {
        File::create("hello.txt").unwrap_or_else(|error| {
            panic!("Problem creating the file: {:?}", error);
        })
    } else {
        panic!("Problem opening the file: {:?}", error);
    }
});
```

Shortcuts:

```rs
let greeting_file = File::open("hello.txt").unwrap(); // dev
let greeting_file = File::open("hello.txt") // production
        .expect("hello.txt should be included in this project");
```

Returning `Result` type from functions

```rs
use std::process;

// Error values will always be string literals with lifetime 'static
fn build(args: &[String]) -> Result<Config, &'static str> { ... }

fn main() {
    let args: Vec<String> = env::args().collect();
    let config = Config::build(&args).unwrap_or_else(|err| {
        println!("Problem parsing arguments: {err}");
        process::exit(1);
    });
    ...
}
```

Propagating Errors to Calling Code:

```rs
use std::fs::File;
use std::io::{self, Read};

fn read_username_from_file() -> Result<String, io::Error> {
    let mut username_file = File::open("hello.txt")?;
    let mut username = String::new();
    username_file.read_to_string(&mut username)?;
    Ok(username)
}

// `?` can be used where the return type matches the caller's

fn read_username_from_file_v2() -> Result<String, io::Error> {
    let mut username = String::new();
    File::open("hello.txt")?.read_to_string(&mut username)?;
    Ok(username)
}

fn read_username_from_file_v3() -> Result<String, io::Error> {
    fs::read_to_string("hello.txt")
}
```

# Unrecoverable Errors

Unrecoverable errors are always a symptom of a bug. Panics occur either by performing an action that causes Rust to panic, or explicitly calling the `panic!` macro. Panicking is sometimes the correct approach in production code, but is most appropriate in tests, prototypes, or example code (this applies to `unwrap()` and `expect()` as well).

When converting prototype code into production code, do a global search for `unwrap()`, `expect()`, and `panic!`, and add in more robust error handling in those sections.

See [To Panic or Not to Panic?](https://rust-book.cs.brown.edu/ch09-03-to-panic-or-not-to-panic.html)

```rs
fn main() {
    panic!("crash and burn");
}
```

### Backtracing to debug a panic

```rs
fn main() {
    let v = vec![1, 2, 3];
    v[99]; // panic!
}
```

Set backtracing on by setting the environment variable `RUST_BACKTRACE` to any value (except 0), assuming not building for release.

```
$ RUST_BACKTRACE=1 cargo run
thread 'main' panicked at 'index out of bounds: the len is 3 but the index is 99', src/main.rs:4:5
stack backtrace:
   0: rust_begin_unwind
             at /rustc/e092d0b6b43f2de967af0887873151bb1c0b18d3/library/std/src/panicking.rs:584:5
   1: core::panicking::panic_fmt
             at /rustc/e092d0b6b43f2de967af0887873151bb1c0b18d3/library/core/src/panicking.rs:142:14
   2: core::panicking::panic_bounds_check
             at /rustc/e092d0b6b43f2de967af0887873151bb1c0b18d3/library/core/src/panicking.rs:84:5
   3: <usize as core::slice::index::SliceIndex<[T]>>::index
             at /rustc/e092d0b6b43f2de967af0887873151bb1c0b18d3/library/core/src/slice/index.rs:242:10
   4: core::slice::index::<impl core::ops::index::Index<I> for [T]>::index
             at /rustc/e092d0b6b43f2de967af0887873151bb1c0b18d3/library/core/src/slice/index.rs:18:9
   5: <alloc::vec::Vec<T,A> as core::ops::index::Index<I>>::index
             at /rustc/e092d0b6b43f2de967af0887873151bb1c0b18d3/library/alloc/src/vec/mod.rs:2591:9
   6: panic::main
             at ./src/main.rs:4:5
   7: core::ops::function::FnOnce::call_once
             at /rustc/e092d0b6b43f2de967af0887873151bb1c0b18d3/library/core/src/ops/function.rs:248:5
note: Some details are omitted, run with `RUST_BACKTRACE=full` for a verbose backtrace.
```

### Custom Types for Validation

```rs
pub struct Guess {
    value: i32,
}

impl Guess {
    pub fn new(value: i32) -> Guess {
        if value < 1 || value > 100 {
            panic!("Guess value must be between 1 and 100, got {}.", value);
        }

        Guess { value }
    }

    pub fn value(&self) -> i32 {
        self.value
    }
}

```
